Error occured when executing function analyze
Traceback (most recent call last):
  File "/home/bluesadi/Yasat/Yasat/utils/timeout.py", line 14, in call_with_timeout
    return func_timeout(timeout, func, args=args)
  File "/home/bluesadi/virtualenvs/Yasat/lib/python3.8/site-packages/func_timeout/dafunc.py", line 108, in func_timeout
    raise_exception(exception)
  File "/home/bluesadi/virtualenvs/Yasat/lib/python3.8/site-packages/func_timeout/py3_raise.py", line 7, in raise_exception
    raise exception[0] from None
  File "/home/bluesadi/Yasat/Yasat/main.py", line 117, in analyze
    misuses = checker.check()
  File "/home/bluesadi/Yasat/Yasat/analyses/rule_checker.py", line 33, in check
    reports += self._check_one(criterion)
  File "/home/bluesadi/Yasat/Yasat/analyses/rule_checker.py", line 56, in _check_one
    callee_addr = self.subject.resolve_external_function(criterion.func_name, criterion.lib)
  File "/home/bluesadi/Yasat/Yasat/knowledge_plugins/subject.py", line 41, in resolve_external_function
    if symbol is not None and symbol.is_import and lib == symbol.resolvedby.name:
AttributeError: 'NoneType' object has no attribute 'name'

Error occured when executing function analyze
Traceback (most recent call last):
  File "/home/bluesadi/Yasat/Yasat/utils/timeout.py", line 14, in call_with_timeout
    return func_timeout(timeout, func, args=args)
  File "/home/bluesadi/virtualenvs/Yasat/lib/python3.8/site-packages/func_timeout/dafunc.py", line 108, in func_timeout
    raise_exception(exception)
  File "/home/bluesadi/virtualenvs/Yasat/lib/python3.8/site-packages/func_timeout/py3_raise.py", line 7, in raise_exception
    raise exception[0] from None
  File "/home/bluesadi/Yasat/Yasat/main.py", line 117, in analyze
    misuses = checker.check()
  File "/home/bluesadi/Yasat/Yasat/analyses/rule_checker.py", line 33, in check
    reports += self._check_one(criterion)
  File "/home/bluesadi/Yasat/Yasat/analyses/rule_checker.py", line 56, in _check_one
    callee_addr = self.subject.resolve_external_function(criterion.func_name, criterion.lib)
  File "/home/bluesadi/Yasat/Yasat/knowledge_plugins/subject.py", line 41, in resolve_external_function
    if symbol is not None and symbol.is_import and lib == symbol.resolvedby.name:
AttributeError: 'NoneType' object has no attribute 'name'

Error occured when executing function analyze
Traceback (most recent call last):
  File "/home/bluesadi/Yasat/Yasat/utils/timeout.py", line 14, in call_with_timeout
    return func_timeout(timeout, func, args=args)
  File "/home/bluesadi/virtualenvs/Yasat/lib/python3.8/site-packages/func_timeout/dafunc.py", line 108, in func_timeout
    raise_exception(exception)
  File "/home/bluesadi/virtualenvs/Yasat/lib/python3.8/site-packages/func_timeout/py3_raise.py", line 7, in raise_exception
    raise exception[0] from None
  File "/home/bluesadi/Yasat/Yasat/main.py", line 117, in analyze
    misuses = checker.check()
  File "/home/bluesadi/Yasat/Yasat/analyses/rule_checker.py", line 33, in check
    reports += self._check_one(criterion)
  File "/home/bluesadi/Yasat/Yasat/analyses/rule_checker.py", line 56, in _check_one
    callee_addr = self.subject.resolve_external_function(criterion.func_name, criterion.lib)
  File "/home/bluesadi/Yasat/Yasat/knowledge_plugins/subject.py", line 41, in resolve_external_function
    if symbol is not None and symbol.is_import and lib == symbol.resolvedby.name:
AttributeError: 'NoneType' object has no attribute 'name'

Error occured when handling /home/bluesadi/Yasat/tests_dev/tmp/D-Link/DAP-1562_FIRMWARE_1.00.ZIP/dap1562_FW_100/_dap1562_FW_100.bin.extracted/squashfs-root/usr/local/lib/mod_auth.so
Error occured when handling statment: 0x404b3c | Call(0x601050<32>, <SimCCO32>: [a0<4>, Conv(8->32, Load(addr=stack_base-768, size=1, endness=Iend_BE))], ret: no-ret-value, fp_ret: no-fp-ret-value)
Traceback (most recent call last):
  File "/home/bluesadi/Yasat/Yasat/analyses/backward_slicing/engine_ail.py", line 77, in _process_Stmt
    self._handle_Stmt(stmt)
  File "/home/bluesadi/Yasat/Yasat/analyses/backward_slicing/engine_ail.py", line 98, in _handle_Stmt
    handler(stmt)
  File "/home/bluesadi/Yasat/Yasat/analyses/backward_slicing/engine_ail.py", line 127, in _ail_handle_Call
    self._ail_handle_CallExpr(stmt)
  File "/home/bluesadi/Yasat/Yasat/analyses/backward_slicing/engine_ail.py", line 165, in _ail_handle_CallExpr
    ret_expr = handler.handle(func, args)
  File "/home/bluesadi/Yasat/Yasat/analyses/backward_slicing/function_handler/function_handler.py", line 27, in handle
    return self.handle_local_function(func, args)
  File "/home/bluesadi/Yasat/Yasat/analyses/backward_slicing/function_handler/interprocedural_function_handler.py", line 14, in handle_local_function
    bs = func.project.analyses.BackwardSlicing(
  File "/home/bluesadi/virtualenvs/Yasat/lib/python3.8/site-packages/angr/analyses/analysis.py", line 144, in __call__
    r = w(*args, **kwargs)
  File "/home/bluesadi/virtualenvs/Yasat/lib/python3.8/site-packages/angr/analyses/analysis.py", line 129, in wrapper
    oself.__init__(*args, **kwargs)
  File "/home/bluesadi/Yasat/Yasat/analyses/backward_slicing/backward_slicing.py", line 102, in __init__
    self.graph = clinic.graph.copy()
AttributeError: 'NoneType' object has no attribute 'copy'

Error occured when handling /home/bluesadi/Yasat/tests_dev/tmp/D-Link/DAP-1562_FIRMWARE_1.00.ZIP/dap1562_FW_100/_dap1562_FW_100.bin.extracted/squashfs-root/usr/local/lib/mod_auth.so
Error occured when handling statment: 0x404b24 | Call(0x601050<32>, <SimCCO32>: [Add(s0<4>, 0x10<32>), Or((Conv(8->32, Load(addr=stack_base-769, size=1, endness=Iend_BE)) << 0x8<8>), ((Conv(8->32, Load(addr=stack_base-775, size=1, endness=Iend_BE)) << 0x10<8>) | Conv(8->32, Load(addr=stack_base-774, size=1, endness=Iend_BE))))], ret: no-ret-value, fp_ret: no-fp-ret-value)
Traceback (most recent call last):
  File "/home/bluesadi/Yasat/Yasat/analyses/backward_slicing/engine_ail.py", line 77, in _process_Stmt
    self._handle_Stmt(stmt)
  File "/home/bluesadi/Yasat/Yasat/analyses/backward_slicing/engine_ail.py", line 98, in _handle_Stmt
    handler(stmt)
  File "/home/bluesadi/Yasat/Yasat/analyses/backward_slicing/engine_ail.py", line 127, in _ail_handle_Call
    self._ail_handle_CallExpr(stmt)
  File "/home/bluesadi/Yasat/Yasat/analyses/backward_slicing/engine_ail.py", line 165, in _ail_handle_CallExpr
    ret_expr = handler.handle(func, args)
  File "/home/bluesadi/Yasat/Yasat/analyses/backward_slicing/function_handler/function_handler.py", line 27, in handle
    return self.handle_local_function(func, args)
  File "/home/bluesadi/Yasat/Yasat/analyses/backward_slicing/function_handler/interprocedural_function_handler.py", line 14, in handle_local_function
    bs = func.project.analyses.BackwardSlicing(
  File "/home/bluesadi/virtualenvs/Yasat/lib/python3.8/site-packages/angr/analyses/analysis.py", line 144, in __call__
    r = w(*args, **kwargs)
  File "/home/bluesadi/virtualenvs/Yasat/lib/python3.8/site-packages/angr/analyses/analysis.py", line 129, in wrapper
    oself.__init__(*args, **kwargs)
  File "/home/bluesadi/Yasat/Yasat/analyses/backward_slicing/backward_slicing.py", line 102, in __init__
    self.graph = clinic.graph.copy()
AttributeError: 'NoneType' object has no attribute 'copy'

Error occured when handling /home/bluesadi/Yasat/tests_dev/tmp/D-Link/DAP-1562_FIRMWARE_1.00.ZIP/dap1562_FW_100/_dap1562_FW_100.bin.extracted/squashfs-root/usr/local/lib/mod_auth.so
Error occured when handling statment: 0x404af8 | Call(0x601050<32>, <SimCCO32>: [Add(s0<4>, 0xc<32>), Or((Conv(8->32, Load(addr=stack_base-770, size=1, endness=Iend_BE)) << 0x8<8>), ((Conv(8->32, Load(addr=stack_base-776, size=1, endness=Iend_BE)) << 0x10<8>) | Conv(8->32, Load(addr=stack_base-764, size=1, endness=Iend_BE))))], ret: no-ret-value, fp_ret: no-fp-ret-value)
Traceback (most recent call last):
  File "/home/bluesadi/Yasat/Yasat/analyses/backward_slicing/engine_ail.py", line 77, in _process_Stmt
    self._handle_Stmt(stmt)
  File "/home/bluesadi/Yasat/Yasat/analyses/backward_slicing/engine_ail.py", line 98, in _handle_Stmt
    handler(stmt)
  File "/home/bluesadi/Yasat/Yasat/analyses/backward_slicing/engine_ail.py", line 127, in _ail_handle_Call
    self._ail_handle_CallExpr(stmt)
  File "/home/bluesadi/Yasat/Yasat/analyses/backward_slicing/engine_ail.py", line 165, in _ail_handle_CallExpr
    ret_expr = handler.handle(func, args)
  File "/home/bluesadi/Yasat/Yasat/analyses/backward_slicing/function_handler/function_handler.py", line 27, in handle
    return self.handle_local_function(func, args)
  File "/home/bluesadi/Yasat/Yasat/analyses/backward_slicing/function_handler/interprocedural_function_handler.py", line 14, in handle_local_function
    bs = func.project.analyses.BackwardSlicing(
  File "/home/bluesadi/virtualenvs/Yasat/lib/python3.8/site-packages/angr/analyses/analysis.py", line 144, in __call__
    r = w(*args, **kwargs)
  File "/home/bluesadi/virtualenvs/Yasat/lib/python3.8/site-packages/angr/analyses/analysis.py", line 129, in wrapper
    oself.__init__(*args, **kwargs)
  File "/home/bluesadi/Yasat/Yasat/analyses/backward_slicing/backward_slicing.py", line 102, in __init__
    self.graph = clinic.graph.copy()
AttributeError: 'NoneType' object has no attribute 'copy'

Error occured when executing function analyze
Traceback (most recent call last):
  File "/home/bluesadi/Yasat/Yasat/utils/timeout.py", line 14, in call_with_timeout
    return func_timeout(timeout, func, args=args)
  File "/home/bluesadi/virtualenvs/Yasat/lib/python3.8/site-packages/func_timeout/dafunc.py", line 108, in func_timeout
    raise_exception(exception)
  File "/home/bluesadi/virtualenvs/Yasat/lib/python3.8/site-packages/func_timeout/py3_raise.py", line 7, in raise_exception
    raise exception[0] from None
  File "/home/bluesadi/Yasat/Yasat/main.py", line 117, in analyze
    misuses = checker.check()
  File "/home/bluesadi/Yasat/Yasat/analyses/rule_checker.py", line 33, in check
    reports += self._check_one(criterion)
  File "/home/bluesadi/Yasat/Yasat/analyses/rule_checker.py", line 56, in _check_one
    callee_addr = self.subject.resolve_external_function(criterion.func_name, criterion.lib)
  File "/home/bluesadi/Yasat/Yasat/knowledge_plugins/subject.py", line 41, in resolve_external_function
    if symbol is not None and symbol.is_import and lib == symbol.resolvedby.name:
AttributeError: 'NoneType' object has no attribute 'name'

